<robot name="parabot">

  <link name="base">
    <visual>
      <origin rpy="0 0 0" xyz="0 0 0"/>
      <geometry>
        <box size="0.001 0.001 0.001"/>
      </geometry>
    </visual>
  </link>

  <link name="Slider_1">
    <visual>
      <origin rpy="0 0 0" xyz="0 0 0"/>
      <geometry>
        <box size="0.08 0.095 0.0365"/>
      </geometry>
      <material name="">
        <color rgba="1 1 1 0.5" />
      </material>
    </visual>
    <collision>
      <origin rpy="0 0 0" xyz="0 0 0"/>
      <geometry>
        <box size="0.08 0.095 0.0365"/>
      </geometry>
    </collision>
    <inertial>
      <origin rpy="0 0 0" xyz="0 0 0"/>
      <mass value="0.696"/>
      <inertia ixx="0.000469246" ixy="9.409e-06" ixz="-3.42e-07" iyy="0.00080749" iyz="4.66e-07" izz="0.000552929"/>
    </inertial>
  </link>

  <joint name="J1" type="continuous">
    <parent link="base" />
    <child link="Slider_1" />
    <origin xyz="0 0 0.0645" rpy="0 0 0" />
    <axis xyz="0 0 1" />
  </joint>

  <gazebo reference="Slider_1">
        <material>Gazebo/Black</material>
  </gazebo>

  <gazebo reference="base">
        <material>Gazebo/Black</material>
  </gazebo>
</robot>


<!-- 需求:设置机器人底盘,并添加摄像头 -->
<robot name="mycar">
    <!-- 1 底盘link -->
    <link name="base_link">
        <!-- 可视化标签 -->
        <visual>
            <!-- 形状 -->
            <geometry>
                <!-- 立方体 -->
                <box size="0.3 0.2 0.1"/>
            </geometry>
            <!-- 偏移量与倾斜弧度 -->
            <!-- xyz:设置分别在xyz上的偏移量
            rpy用于设置xyz三个方向的旋转角 -->
            <origin xyz='0 0 0' rpy='0 0 0'/>

            <!-- 颜色 -->
            <!-- rgba:
            rgb三原色,a透明度,四个值取值都在0到1之间 -->
            <material name="car_color">
                <color rgba = "0.3 0.4 0.8 0.8"/>
            </material>
        </visual>
    </link>

    <!-- 2 摄像头link -->
    <link name="camera">
        <!-- 可视化标签 -->
        <visual>
            <!-- 形状 -->
            <geometry>
                <!-- 立方体 -->
                <box size="0.03 0.05 0.05"/>
            </geometry>
            <!-- 偏移量与倾斜弧度 -->
            <!-- xyz:设置分别在xyz上的偏移量
            rpy用于设置xyz三个方向的旋转角 -->
            <origin xyz='0 0 0.025' rpy='0 0 0'/>
            <!-- 需要上移半个摄像头的高度,才不会导致摄像头内嵌在机器人车体里 -->
            <!-- 颜色 -->
            <!-- rgba:
            rgb三原色,a透明度,四个值取值都在0到1之间 -->
            <material name="car_color">
                <color rgba = "0 1 0 0.8"/>
            </material>
        </visual>
    </link>
    <!-- 3 关节 -->
    <joint name="camera_to_link" type="continuous">
        <!-- 父级link -->
        <parent link="base_link"/>
        <!-- 子级link -->
        <child link="camera"/>
        <!-- 设置偏移量 -->
        <origin xyz='0.13 0 0.05' rpy='0 0 0'/>
        <!-- 设置关节旋转参考的坐标轴 -->
        <axis xyz='0 0 1'/>
    </joint>

    <gazebo reference="base_link">
        <material>Gazebo/Black</material>
  </gazebo>

  <gazebo reference="camera">
        <material>Gazebo/Black</material>
  </gazebo>
</robot>


